# Generated by Django 3.0.2 on 2020-01-02 18:07

from django.conf import settings
import django.contrib.auth.validators
from django.db import migrations, models
import django.db.models.deletion


class Migration(migrations.Migration):

    dependencies = [
        ('main', '0003_auto_20200101_1946'),
    ]

    operations = [
        migrations.AlterField(
            model_name='customuser',
            name='last_name',
            field=models.CharField(blank=True, max_length=150, verbose_name='last name'),
        ),
        migrations.AlterField(
            model_name='customuser',
            name='orgranization',
            field=models.ForeignKey(blank=True, null=True, on_delete=django.db.models.deletion.DO_NOTHING, related_name='user_organization', to='main.Organization'),
        ),
        migrations.AlterField(
            model_name='customuser',
            name='username',
            field=models.CharField(error_messages={'unique': 'A user with that username already exists.'}, help_text='Required. 150 characters or fewer. Letters, digits and @/./+/-/_ only.', max_length=150, unique=True, validators=[django.contrib.auth.validators.UnicodeUsernameValidator()], verbose_name='username'),
        ),
        migrations.AlterField(
            model_name='organization',
            name='members',
            field=models.ManyToManyField(to=settings.AUTH_USER_MODEL),
        ),
    ]
